<?xml version='1.0'?>
<sdf version='1.6'>
  <model name="mini_talon_vtail">
    <pose>0 0 0.1 0 0 0</pose>

    <link name="base_link">
      <inertial>
        <pose>0 0 0 0 0 0</pose>
        <mass>1.8</mass>
        <inertia>
          <ixx>0.024607948</ixx>
          <ixy>0</ixy>
          <ixz>0</ixz>
          <iyy>0.086155637</iyy>
          <iyz>0</iyz>
          <izz>0.103828985</izz>
        </inertia>
      </inertial>

      <collision name="fuselage_collision">
        <pose>0 0 0 0 0 0</pose>
        <geometry>
          <box>
            <size>0.608 0.391 0.353</size>
          </box>
        </geometry>
      </collision>

      <collision name="left_wing_collision">
        <pose>0 0 0 0 0 0</pose>
        <geometry>
          <mesh>
            <uri>model://mini_talon_vtail/meshes/mini_talon_left_wing_collision.stl</uri>
          </mesh>
        </geometry>
      </collision>

      <collision name="right_wing_collision">
        <pose>0 0 0 0 0 0</pose>
        <geometry>
          <mesh>
            <uri>model://mini_talon_vtail/meshes/mini_talon_right_wing_collision.stl</uri>
          </mesh>
        </geometry>
      </collision>

      <collision name="left_tail_collision">
        <pose>0 0 0 0 0 0</pose>
        <geometry>
          <mesh>
            <uri>model://mini_talon_vtail/meshes/mini_talon_left_tail_collision.stl</uri>
          </mesh>
        </geometry>
      </collision>

      <collision name="right_tail_collision">
        <pose>0 0 0 0 0 0</pose>
        <geometry>
          <mesh>
            <uri>model://mini_talon_vtail/meshes/mini_talon_right_tail_collision.stl</uri>
          </mesh>
        </geometry>
      </collision>

      <visual name="fuselage_visual">
        <pose>0 0 0 0 0 0</pose>
        <geometry>
          <mesh>
            <uri>model://mini_talon_vtail/meshes/mini_talon_fuselage.dae</uri>
          </mesh>
        </geometry>
      </visual>

      <visual name="forward_deck_visual">
        <pose>0 0 0 0 0 0</pose>
        <geometry>
          <mesh>
            <uri>model://mini_talon_vtail/meshes/mini_talon_forward_deck.dae</uri>
          </mesh>
        </geometry>
      </visual>

      <visual name="left_wing_visual">
        <pose>0 0 0 0 0 0</pose>
        <geometry>
          <mesh>
            <uri>model://mini_talon_vtail/meshes/mini_talon_left_wing.dae</uri>
          </mesh>
        </geometry>
      </visual>

      <visual name="right_wing_visual">
        <pose>0 0 0 0 0 0</pose>
        <geometry>
          <mesh>
            <uri>model://mini_talon_vtail/meshes/mini_talon_right_wing.dae</uri>
          </mesh>
        </geometry>
      </visual>

      <visual name="left_tail_visual">
        <pose>0 0 0 0 0 0</pose>
        <geometry>
          <mesh>
            <uri>model://mini_talon_vtail/meshes/mini_talon_left_tail.dae</uri>
          </mesh>
        </geometry>
      </visual>

      <visual name="right_tail_visual">
        <pose>0 0 0 0 0 0</pose>
        <geometry>
          <mesh>
            <uri>model://mini_talon_vtail/meshes/mini_talon_right_tail.dae</uri>
          </mesh>
        </geometry>
      </visual>

      <visual name="motor_plate_visual">
        <pose>-0.41 0 -0.03 0 1.57 0</pose>
        <geometry>
          <mesh>
            <uri>model://mini_talon_vtail/meshes/propdrive_3536_frontplate.dae</uri>
          </mesh>
        </geometry>
      </visual>

      <!-- Sensors. -->
      <sensor name="imu_sensor" type="imu">
        <pose>0 0 0 3.14 0 0</pose>
        <always_on>1</always_on>
        <update_rate>1000.0</update_rate>
      </sensor>
      <sensor name="navsat_sensor" type="navsat">
        <always_on>1</always_on>
        <update_rate>1</update_rate>
      </sensor>
    </link>

<!--
    <link name="main_wheel_link">
      <pose>0.302018 0 -0.097974 1.57 0 0</pose>
      <inertial>
        <mass>0.01</mass>
        <inertia>
          <ixx>1.01896E-06</ixx>
          <ixy>0</ixy>
          <ixz>0</ixz>
          <iyy>1.01896E-06</iyy>
          <iyz>0</iyz>
          <izz>1.71125E-06</izz>
        </inertia>
      </inertial>
      <collision name="main_wheel_collision">
        <geometry>
          <mesh>
            <uri>model://mini_talon_vtail/meshes/mini_talon_main_wheel_collision.stl</uri>
          </mesh>
        </geometry>
      </collision>
      <visual name="main_wheel_visual">
        <geometry>
          <mesh>
            <uri>model://mini_talon_vtail/meshes/mini_talon_main_wheel.dae</uri>
          </mesh>
        </geometry>
      </visual>
    </link>
    <joint name="main_wheel_joint" type="revolute">
      <pose>0 0 0 0 0 0</pose>
      <parent>base_link</parent>
      <child>main_wheel_link</child>
      <axis>
        <xyz>0 0 -1</xyz>
        <limit>
          <lower>-1.0e-16</lower>
          <upper>1.0e+16</upper>
        </limit>
        <dynamics>
          <damping>0.0001</damping>
        </dynamics>
      </axis>
    </joint>
-->
    <link name="left_aileron_link">
      <pose>-0.107 0.371 0.0174 0 0 0</pose>
      <inertial>
        <mass>0.01</mass>
        <inertia>
          <ixx>4.68283E-05</ixx>
          <ixy>0</ixy>
          <ixz>0</ixz>
          <iyy>2.54167E-06</iyy>
          <iyz>0</iyz>
          <izz>4.93283E-05</izz>
        </inertia>
      </inertial>
      <collision name="left_aileron_collision">
        <geometry>
          <mesh>
            <uri>model://mini_talon_vtail/meshes/mini_talon_left_aileron.dae</uri>
          </mesh>
        </geometry>
      </collision>
      <visual name="left_aileron_visual">
        <geometry>
          <mesh>
            <uri>model://mini_talon_vtail/meshes/mini_talon_left_aileron.dae</uri>
          </mesh>
        </geometry>
      </visual>
    </link>
    <joint name="left_aileron_joint" type="revolute">
      <pose>0.015 0 0 0 0 0</pose>
      <parent>base_link</parent>
      <child>left_aileron_link</child>
      <axis>
        <xyz>0 1 0</xyz>
        <limit>
          <lower>-0.523599</lower>
          <upper>0.523599</upper>
        </limit>
        <dynamics>
          <damping>0.0001</damping>
        </dynamics>
      </axis>
    </joint>

    <link name="right_aileron_link">
      <pose>-0.107 -0.371 0.0174 0 0 0</pose>
      <inertial>
        <mass>0.01</mass>
        <inertia>
          <ixx>4.68283E-05</ixx>
          <ixy>0</ixy>
          <ixz>0</ixz>
          <iyy>2.54167E-06</iyy>
          <iyz>0</iyz>
          <izz>4.93283E-05</izz>
        </inertia>
      </inertial>
      <collision name="right_aileron_collision">
        <pose>0.005 -0.002 0 0 0 0</pose>
        <geometry>
          <mesh>
            <uri>model://mini_talon_vtail/meshes/mini_talon_right_aileron.dae</uri>
          </mesh>
        </geometry>
      </collision>
      <visual name="right_aileron_visual">
        <pose>0.005 -0.002 0 0 0 0</pose>
        <geometry>
          <mesh>
            <uri>model://mini_talon_vtail/meshes/mini_talon_right_aileron.dae</uri>
          </mesh>
        </geometry>
      </visual>
    </link>
    <joint name="right_aileron_joint" type="revolute">
      <pose>0.015 0 0 0 0 0</pose>
      <parent>base_link</parent>
      <child>right_aileron_link</child>
      <axis>
        <xyz>0 1 0</xyz>
        <limit>
          <lower>-0.523599</lower>
          <upper>0.523599</upper>
        </limit>
        <dynamics>
          <damping>0.0001</damping>
        </dynamics>
      </axis>
    </joint>

    <link name="left_ruddervator_link">
      <pose>-0.365 0.077 0.045 0.785 -0.174 0.1047</pose>
      <inertial>
        <mass>0.01</mass>
        <inertia>
          <ixx>1.97842E-05</ixx>
          <ixy>0</ixy>
          <ixz>0</ixz>
          <iyy>3.02083E-06</iyy>
          <iyz>0</iyz>
          <izz>2.27633E-05</izz>
        </inertia>
      </inertial>
      <collision name="left_ruddervator_collision">
        <geometry>
          <mesh>
            <uri>model://mini_talon_vtail/meshes/mini_talon_left_ruddervator.dae</uri>
          </mesh>
        </geometry>
      </collision>
      <visual name="left_ruddervator_visual">
        <geometry>
          <mesh>
            <uri>model://mini_talon_vtail/meshes/mini_talon_left_ruddervator.dae</uri>
          </mesh>
        </geometry>
      </visual>
    </link>
    <joint name="left_ruddervator_joint" type="revolute">
      <pose>0.01 0 0 0 0 0</pose>
      <parent>base_link</parent>
      <child>left_ruddervator_link</child>
      <axis>
        <xyz>0 1 0</xyz>
        <limit>
          <lower>-0.523599</lower>
          <upper>0.523599</upper>
        </limit>
        <dynamics>
          <damping>0.0001</damping>
        </dynamics>
      </axis>
    </joint>

    <link name="right_ruddervator_link">
      <pose>-0.365 -0.077 0.045 -0.785 -0.174 -0.1047</pose>
      <inertial>
        <mass>0.01</mass>
        <inertia>
          <ixx>1.97842E-05</ixx>
          <ixy>0</ixy>
          <ixz>0</ixz>
          <iyy>3.02083E-06</iyy>
          <iyz>0</iyz>
          <izz>2.27633E-05</izz>
        </inertia>
      </inertial>
      <collision name="right_ruddervator_collision">
        <geometry>
          <mesh>
            <uri>model://mini_talon_vtail/meshes/mini_talon_right_ruddervator.dae</uri>
          </mesh>
        </geometry>
      </collision>
      <visual name="right_ruddervator_visual">
        <geometry>
          <mesh>
            <uri>model://mini_talon_vtail/meshes/mini_talon_right_ruddervator.dae</uri>
          </mesh>
        </geometry>
      </visual>
    </link>
    <joint name="right_ruddervator_joint" type="revolute">
      <pose>0.01 0 0 0 0 0</pose>
      <parent>base_link</parent>
      <child>right_ruddervator_link</child>
      <axis>
        <xyz>0 1 0</xyz>
        <limit>
          <lower>-0.523599</lower>
          <upper>0.523599</upper>
        </limit>
        <dynamics>
          <damping>0.0001</damping>
        </dynamics>
      </axis>
    </joint>


    <link name="motor_link">
      <pose>-0.41 0 -0.03 0 1.57 0</pose>
      <inertial>
        <mass>0.025</mass>
        <inertia>
          <ixx>9.75e-06</ixx>
          <ixy>0</ixy>
          <ixz>0</ixz>
          <iyy>0.000166704</iyy>
          <iyz>0</iyz>
          <izz>0.000167604</izz>
        </inertia>
      </inertial>

      <collision name="motor_collision">
        <pose>0 0 0.018 0 0 0</pose>
        <geometry>
          <cylinder>
            <radius>0.0175</radius>
            <length>0.036</length>
          </cylinder>
        </geometry>
      </collision>
      <collision name="propeller_collision">
        <pose>0 0 -0.005 0 0 0</pose>
        <geometry>
          <cylinder>
            <radius>0.1</radius>
            <length>0.005</length>
          </cylinder>
        </geometry>
      </collision>
      <visual name="motor_visual">
        <geometry>
          <mesh>
            <uri>model://mini_talon_vtail/meshes/propdrive_3536_motor_can.dae</uri>
          </mesh>
        </geometry>
      </visual>
      <visual name="propeller_visual">
        <pose>0 0 -0.005 0 0 0</pose>
        <geometry>
          <mesh>
            <uri>model://mini_talon_vtail/meshes/iris_prop_ccw.dae</uri>
          </mesh>
        </geometry>
        <material>
          <ambient>0.01 0.01 0.01 1</ambient>
          <diffuse>0.01 0.01 0.01 1</diffuse>
          <specular>0.01 0.01 0.01 1</specular>
        </material>
      </visual>
    </link>
    <joint name="motor_joint" type="revolute">
      <pose>0 0 0 0 3.14 0</pose>
      <parent>base_link</parent>
      <child>motor_link</child>
      <axis>
        <xyz>0 0 1</xyz>
        <limit>
          <lower>-1.0e-16</lower>
          <upper>1.0e+16</upper>
        </limit>
        <dynamics>
          <damping>0.004</damping>
        </dynamics>
      </axis>
    </joint>

    <link name='mini_talon_vtail/imu_link'>
      <pose>0 0 0 0 0 0</pose>
      <inertial>
        <pose>0 0 0 0 0 0</pose>
        <mass>0.015</mass>
        <inertia>
          <ixx>1e-05</ixx>
          <ixy>0</ixy>
          <ixz>0</ixz>
          <iyy>1e-05</iyy>
          <iyz>0</iyz>
          <izz>1e-05</izz>
        </inertia>
      </inertial>
    </link>
    <joint name='mini_talon_vtail/imu_joint' type='revolute'>
      <child>mini_talon_vtail/imu_link</child>
      <parent>base_link</parent>
      <axis>
        <xyz>1 0 0</xyz>
        <limit>
          <lower>0</lower>
          <upper>0</upper>
          <effort>0</effort>
          <velocity>0</velocity>
        </limit>
        <dynamics>
          <spring_reference>0</spring_reference>
          <spring_stiffness>0</spring_stiffness>
        </dynamics>
        <use_parent_model_frame>1</use_parent_model_frame>
      </axis>
    </joint>

    <include>
      <uri>model://airspeed</uri>
      <pose>0 0 0 0 0 0</pose>
      <name>airspeed</name>
    </include>
    <joint name='airspeed_joint' type='fixed'>
      <child>airspeed::link</child>
      <parent>base_link</parent>
    </joint>
    <include>
      <uri>model://gps</uri>
      <pose>0 0 0 0 0 0</pose>
      <name>gps</name>
    </include>
    <joint name='gps_joint' type='fixed'>
      <child>gps::link</child>
      <parent>base_link</parent>
    </joint>


    <!-- System plugins -->
    <!-- left wing -->
    <plugin name="left_wing" filename="libLiftDragPlugin.so">
      <a0>0.13</a0>
      <cla>3.7</cla>
      <cda>0.06417112299</cda>
      <cma>0</cma>
      <alpha_stall>0.3391428111</alpha_stall>
      <cla_stall>-3.85</cla_stall>
      <cda_stall>-0.9233984055</cda_stall>
      <cma_stall>0</cma_stall>
      <cp>0 0.27 0.029</cp>
      <area>0.16</area>
      <air_density>1.2041</air_density>
      <forward>1 0 0</forward>
      <upward>0 0 1</upward>
      <link_name>base_link</link_name>
      <robotNamespace></robotNamespace>
      <windSubTopic>world_wind</windSubTopic>
    </plugin>

    <!-- right wing -->
    <plugin name="right_wing" filename="libLiftDragPlugin.so">
      <a0>0.13</a0>
      <cla>3.7</cla>
      <cda>0.06417112299</cda>
      <cma>0</cma>
      <alpha_stall>0.3391428111</alpha_stall>
      <cla_stall>-3.85</cla_stall>
      <cda_stall>-0.9233984055</cda_stall>
      <cma_stall>0</cma_stall>
      <cp>0 -0.27 0.029</cp>
      <area>0.16</area>
      <air_density>1.2041</air_density>
      <forward>1 0 0</forward>
      <upward>0 0 1</upward>
      <link_name>base_link</link_name>
      <robotNamespace></robotNamespace>
      <windSubTopic>world_wind</windSubTopic>
    </plugin>

    <!-- left aileron -->
    <plugin name="left_aileron" filename="libLiftDragPlugin.so">
      <a0>0.13</a0>
      <cla>3.7</cla>
      <cda>0.06417112299</cda>
      <cma>0.0</cma>
      <alpha_stall>0.3391428111</alpha_stall>
      <cla_stall>-3.85</cla_stall>
      <cda_stall>-0.9233984055</cda_stall>
      <cma_stall>0</cma_stall>
      <cp>0 0.27 0.029</cp>
      <area>0.011</area>
      <air_density>1.2041</air_density>
      <forward>1 0 0</forward>
      <upward>0 0 1</upward>
      <link_name>base_link</link_name>
      <control_joint_name>
        left_aileron_joint
      </control_joint_name>
      <control_joint_rad_to_cl>-4.0</control_joint_rad_to_cl>
      <robotNamespace></robotNamespace>
      <windSubTopic>world_wind</windSubTopic>
    </plugin>

    <!-- right aileron -->
    <plugin name="right_aileron" filename="libLiftDragPlugin.so">
      <a0>0.13</a0>
      <cla>3.7</cla>
      <cda>0.06417112299</cda>
      <cma>0.0</cma>
      <alpha_stall>0.3391428111</alpha_stall>
      <cla_stall>-3.85</cla_stall>
      <cda_stall>-0.9233984055</cda_stall>
      <cma_stall>0</cma_stall>
      <cp>0 -0.27 0.029</cp>
      <area>0.11</area>
      <air_density>1.2041</air_density>
      <forward>1 0 0</forward>
      <upward>0 0 1</upward>
      <link_name>base_link</link_name>
      <control_joint_name>
        right_aileron_joint
      </control_joint_name>
      <control_joint_rad_to_cl>-4.0</control_joint_rad_to_cl>
      <robotNamespace></robotNamespace>
      <windSubTopic>world_wind</windSubTopic>
    </plugin>

    <!-- left v-tail -->
    <plugin name="left_vtail" filename="libLiftDragPlugin.so">
      <a0>0.13</a0>
      <cla>3.7</cla>
      <cda>0.06417112299</cda>
      <cma>0.0</cma>
      <alpha_stall>0.3391428111</alpha_stall>
      <cla_stall>-3.85</cla_stall>
      <cda_stall>-0.9233984055</cda_stall>
      <cma_stall>0</cma_stall>
      <cp>-0.33 0.08 0.051</cp>
      <area>0.025</area>
      <air_density>1.2041</air_density>
      <forward>1 0 0</forward>
      <upward>0 1 1</upward>
      <link_name>base_link</link_name>
      <robotNamespace></robotNamespace>
      <windSubTopic>world_wind</windSubTopic>
    </plugin>

    <!-- right v-tail -->
    <plugin name="right_vtail" filename="libLiftDragPlugin.so">
      <a0>0.13</a0>
      <cla>3.7</cla>
      <cda>0.06417112299</cda>
      <cma>0.0</cma>
      <alpha_stall>0.3391428111</alpha_stall>
      <cla_stall>-3.85</cla_stall>
      <cda_stall>-0.9233984055</cda_stall>
      <cma_stall>0</cma_stall>
      <cp>-0.33 -0.08 0.051</cp>
      <area>0.025</area>
      <air_density>1.2041</air_density>
      <forward>1 0 0</forward>
      <upward>0 -1 1</upward>
      <link_name>base_link</link_name>
      <robotNamespace></robotNamespace>
      <windSubTopic>world_wind</windSubTopic>
    </plugin>

    <!-- left ruddervator -->
    <plugin name="left_ruddervator" filename="libLiftDragPlugin.so">
      <a0>0.13</a0>
      <cla>3.7</cla>
      <cda>0.06417112299</cda>
      <cma>0.0</cma>
      <alpha_stall>0.3391428111</alpha_stall>
      <cla_stall>-3.85</cla_stall>
      <cda_stall>-0.9233984055</cda_stall>
      <cma_stall>0</cma_stall>
      <cp>-0.33 0.08 0.051</cp>
      <area>0.007</area>
      <air_density>1.2041</air_density>
      <forward>1 0 0</forward>
      <upward>0 1 1</upward>
      <link_name>base_link</link_name>
      <control_joint_name>
        left_ruddervator_joint
      </control_joint_name>
      <control_joint_rad_to_cl>-6.0</control_joint_rad_to_cl>
      <robotNamespace></robotNamespace>
      <windSubTopic>world_wind</windSubTopic>
    </plugin>

    <!-- right ruddervator -->
    <plugin name="right_ruddervator" filename="libLiftDragPlugin.so">
      <a0>0.13</a0>
      <cla>3.7</cla>
      <cda>0.06417112299</cda>
      <cma>0.0</cma>
      <alpha_stall>0.3391428111</alpha_stall>
      <cla_stall>-3.85</cla_stall>
      <cda_stall>-0.9233984055</cda_stall>
      <cma_stall>0</cma_stall>
      <cp>-0.33 -0.08 0.051</cp>
      <area>0.007</area>
      <air_density>1.2041</air_density>
      <forward>1 0 0</forward>
      <upward>0 -1 1</upward>
      <link_name>base_link</link_name>
      <control_joint_name>
        left_ruddervator_joint
      </control_joint_name>
      <control_joint_rad_to_cl>-6.0</control_joint_rad_to_cl>
      <robotNamespace></robotNamespace>
      <windSubTopic>world_wind</windSubTopic>
    </plugin>

    <!-- puller -->
    <plugin name='puller' filename='libgazebo_motor_model.so'>
      <robotNamespace></robotNamespace>
      <jointName>motor_joint</jointName>
      <linkName>motor_link</linkName>
      <turningDirection>cw</turningDirection>
      <timeConstantUp>0.0125</timeConstantUp>
      <timeConstantDown>0.025</timeConstantDown>
      <maxRotVelocity>3500</maxRotVelocity>
      <motorConstant>8.54858e-06</motorConstant>
      <momentConstant>0.01</momentConstant>
      <commandSubTopic>/gazebo/command/motor_speed</commandSubTopic>
      <motorNumber>1</motorNumber>
      <rotorDragCoefficient>8.06428e-05</rotorDragCoefficient>
      <rollingMomentCoefficient>1e-06</rollingMomentCoefficient>
      <motorSpeedPubTopic>/motor_speed/1</motorSpeedPubTopic>
      <rotorVelocitySlowdownSim>10</rotorVelocitySlowdownSim>
      <robotNamespace></robotNamespace>
      <windSubTopic>world_wind</windSubTopic>
    </plugin>

    <!-- sensor -->
    <plugin name='gazebo_imu_plugin' filename='libgazebo_imu_plugin.so'>
      <robotNamespace></robotNamespace>
      <linkName>mini_talon_vtail/imu_link</linkName>
      <imuTopic>/imu</imuTopic>
      <gyroscopeNoiseDensity>0.0003394</gyroscopeNoiseDensity>
      <gyroscopeRandomWalk>3.8785e-05</gyroscopeRandomWalk>
      <gyroscopeBiasCorrelationTime>1000.0</gyroscopeBiasCorrelationTime>
      <gyroscopeTurnOnBiasSigma>0.0087</gyroscopeTurnOnBiasSigma>
      <accelerometerNoiseDensity>0.004</accelerometerNoiseDensity>
      <accelerometerRandomWalk>0.006</accelerometerRandomWalk>
      <accelerometerBiasCorrelationTime>300.0</accelerometerBiasCorrelationTime>
      <accelerometerTurnOnBiasSigma>0.196</accelerometerTurnOnBiasSigma>
    </plugin>
    <plugin name='groundtruth_plugin' filename='libgazebo_groundtruth_plugin.so'>
      <robotNamespace></robotNamespace>
    </plugin>
    <plugin name='magnetometer_plugin' filename='libgazebo_magnetometer_plugin.so'>
      <robotNamespace/>
      <pubRate>100</pubRate>
      <noiseDensity>0.0004</noiseDensity>
      <randomWalk>6.4e-06</randomWalk>
      <biasCorrelationTime>600</biasCorrelationTime>
      <magTopic>/mag</magTopic>
    </plugin>
    <plugin name='barometer_plugin' filename='libgazebo_barometer_plugin.so'>
      <robotNamespace/>
      <pubRate>50</pubRate>
      <baroTopic>/baro</baroTopic>
    </plugin>

    <plugin name='mavlink_interface' filename='libgazebo_mavlink_interface.so'>
      <robotNamespace></robotNamespace>
      <imuSubTopic>/imu</imuSubTopic>
      <magSubTopic>/mag</magSubTopic>
      <baroSubTopic>/baro</baroSubTopic>
      <mavlink_tcp_port>{{ mavlink_tcp_port }}</mavlink_tcp_port>
      <mavlink_udp_port>{{ mavlink_udp_port }}</mavlink_udp_port>
      <serialEnabled>{{ serial_enabled }}</serialEnabled>
      <serialDevice>{{ serial_device }}</serialDevice>
      <baudRate>{{ serial_baudrate }}</baudRate>
      <qgc_addr>INADDR_ANY</qgc_addr>
      <qgc_udp_port>14550</qgc_udp_port>
      <sdk_addr>INADDR_ANY</sdk_addr>
      <sdk_udp_port>14540</sdk_udp_port>
      <hil_mode>{{ hil_mode }}</hil_mode>
      <hil_state_level>false</hil_state_level>
      <enable_lockstep>true</enable_lockstep>
      <use_tcp>true</use_tcp>
      <motorSpeedCommandPubTopic>/gazebo/command/motor_speed</motorSpeedCommandPubTopic>
      <control_channels>
        <channel name="rotor1">
          <input_index>6</input_index>
          <input_offset>0</input_offset>
          <input_scaling>3500</input_scaling>
          <zero_position_disarmed>0</zero_position_disarmed>
          <zero_position_armed>0</zero_position_armed>
          <joint_control_type>velocity</joint_control_type>
          <joint_name>motor_joint</joint_name>
        </channel>
        <channel name="left_elevon">
          <input_index>2</input_index>
          <input_offset>-0.5</input_offset>
          <input_scaling>1.0471976</input_scaling>
          <zero_position_disarmed>0</zero_position_disarmed>
          <zero_position_armed>0</zero_position_armed>
          <joint_control_type>position_kinematic</joint_control_type>
          <joint_name>left_aileron_joint</joint_name>
        </channel>
        <channel name="right_elevon">
          <input_index>3</input_index>
          <input_offset>-0.5</input_offset>
          <input_scaling>1.0471976</input_scaling>
          <zero_position_disarmed>0</zero_position_disarmed>
          <zero_position_armed>0</zero_position_armed>
          <joint_control_type>position_kinematic</joint_control_type>
          <joint_name>right_aileron_joint</joint_name>
  	    </channel>
        <channel name="left_ruddervator">
          <input_index>4</input_index>
          <input_offset>-0.5</input_offset>
          <input_scaling>1.0471976</input_scaling>
          <zero_position_disarmed>0</zero_position_disarmed>
          <zero_position_armed>0</zero_position_armed>
          <joint_control_type>position_kinematic</joint_control_type>
          <joint_name>left_ruddervator_joint</joint_name>
        </channel>
        <channel name="right_ruddervator">
          <input_index>5</input_index>
          <input_offset>-0.5</input_offset>
          <input_scaling>1.0471976</input_scaling>
          <zero_position_disarmed>0</zero_position_disarmed>
          <zero_position_armed>0</zero_position_armed>
          <joint_control_type>position_kinematic</joint_control_type>
          <joint_name>right_ruddervator_joint</joint_name>
  	    </channel>
        <!--
        <channel name="wheel">
          <input_index>7</input_index>
          <input_offset></input_offset>
          <input_scaling>1000</input_scaling>
          <zero_position_disarmed>0</zero_position_disarmed>
          <zero_position_armed>0</zero_position_armed>
          <joint_control_type>velocity</joint_control_type>
          <joint_name>main_wheel_joint</joint_name>
  	    </channel>
        -->
      </control_channels>
    </plugin>


  </model>
</sdf>

<!-- 
  Motor thrust calcs (initial estimates)

  PropDrive 3536 910kV motor
  3S battery (11.1V)
  rpm_max = 10000
  rpm = 8000
  ang_max = 1057
  ang_vel = 837
  10x7 prop

  Inertials

  fuselage:
  mass: 
  radius: 0.16 m
  length: 0.8 m

  main wheel:
  mass: 
  radius: 0.0135 m
  length: 0.014 m

  L/R wing
  mass: 
  area: 0.65 x 0.245 = 0.16 m^2
  cp: 

  L/R aileron
  mass:
  area: 0.237 x 0.0477 = 0.011 m^2
  cp: 

  L/R v-tail
  mass: 
  area: 0.126 x 0.197 = 0.025 m^2
  cp: 

  L/R ruddervator
  mass: 
  area: 0.042 x 0.154 = 0.0065 m^2
  cp: 

  Position and thrust controller commands

  Thrust:

  gz topic -t /model/mini_talon_vtail/joint/motor_joint/cmd_vel -m gz.msgs.Double -p 'data: 1000'

  Aileron:

  gz topic -t /right_aileron_joint/cmd_pos -m gz.msgs.Double -p 'data: 1'

  Ruddervator:

  gz topic -t /left_ruddervator_joint/cmd_pos -m gz.msgs.Double -p 'data: 1'

  -->

